I'm sorry, but an uncaught exception occurred.

While running game code:
  File "game/venaprologue.rpy", line 265, in script
    scene shd with vpunch(3.0)
  File "game/venaprologue.rpy", line 265, in <module>
    scene shd with vpunch(3.0)
Exception: Not a displayable: 3.0

-- Full Traceback ------------------------------------------------------------

Full traceback:
  File "game/venaprologue.rpy", line 265, in script
    scene shd with vpunch(3.0)
  File "renpy/ast.py", line 1439, in execute
    paired = renpy.python.py_eval(self.paired)
  File "renpy/python.py", line 2276, in py_eval
    return py_eval_bytecode(code, globals, locals)
  File "renpy/python.py", line 2269, in py_eval_bytecode
    return eval(bytecode, globals, locals)
  File "game/venaprologue.rpy", line 265, in <module>
    scene shd with vpunch(3.0)
  File "renpy/curry.py", line 48, in __call__
    return self.callable(*(self.args + args), **merged_kwargs)
  File "renpy/display/motion.py", line 308, in Move
    **properties)
  File "renpy/display/motion.py", line 102, in __init__
    self.add(child)
  File "renpy/display/layout.py", line 201, in add
    child = renpy.easy.displayable(d)
  File "renpy/easy.py", line 139, in displayable
    raise Exception("Not a displayable: %r" % (d,))
Exception: Not a displayable: 3.0

Windows-10-10.0.22000
Ren'Py 7.4.10.2178
The Calling 1.0
Tue Aug  2 19:16:29 2022
